<?xml version="1.0"?>
<robot xmlns:xacro="http://www.ros.org/wiki/xacro" name="minimal_mobile_base">
  <xacro:property name="base_length" value="0.40"/>
  <xacro:property name="base_width" value="0.30"/>
  <xacro:property name="base_height" value="0.10"/>
  <xacro:property name="base_mass" value="2.0"/>

  <xacro:property name="wheel_radius" value="0.05"/>
  <xacro:property name="wheel_width" value="0.03"/>
  <xacro:property name="wheel_mass" value="0.20"/>
  <xacro:property name="wheel_y" value="${base_width / 2.0 + wheel_width / 2.0}"/>
  <xacro:property name="wheel_z" value="${-base_height / 2.0 + wheel_radius}"/>
  <xacro:property name="caster_radius" value="0.025"/>

  <material name="body_blue">
    <color rgba="0.1 0.25 0.8 1.0"/>
  </material>

  <material name="wheel_dark">
    <color rgba="0.05 0.05 0.05 1.0"/>
  </material>

  <xacro:macro name="box_inertial" params="mass x y z">
    <inertial>
      <origin xyz="0 0 0" rpy="0 0 0"/>
      <mass value="${mass}"/>
      <inertia
        ixx="${mass / 12.0 * (y*y + z*z)}"
        ixy="0.0"
        ixz="0.0"
        iyy="${mass / 12.0 * (x*x + z*z)}"
        iyz="0.0"
        izz="${mass / 12.0 * (x*x + y*y)}"/>
    </inertial>
  </xacro:macro>

  <xacro:macro name="cylinder_inertial_y_axis" params="mass radius length">
    <inertial>
      <origin xyz="0 0 0" rpy="0 0 0"/>
      <mass value="${mass}"/>
      <inertia
        ixx="${mass / 12.0 * (3.0*radius*radius + length*length)}"
        ixy="0.0"
        ixz="0.0"
        iyy="${0.5 * mass * radius * radius}"
        iyz="0.0"
        izz="${mass / 12.0 * (3.0*radius*radius + length*length)}"/>
    </inertial>
  </xacro:macro>

  <link name="base_link">
    <visual>
      <origin xyz="0 0 0" rpy="0 0 0"/>
      <geometry>
        <box size="${base_length} ${base_width} ${base_height}"/>
      </geometry>
      <material name="body_blue"/>
    </visual>
    <collision>
      <origin xyz="0 0 0" rpy="0 0 0"/>
      <geometry>
        <box size="${base_length} ${base_width} ${base_height}"/>
      </geometry>
    </collision>
    <xacro:box_inertial mass="${base_mass}" x="${base_length}" y="${base_width}" z="${base_height}"/>
  </link>

  <xacro:macro name="wheel" params="prefix y_sign">
    <link name="${prefix}_wheel_link">
      <visual>
        <origin xyz="0 0 0" rpy="1.5708 0 0"/>
        <geometry>
          <cylinder radius="${wheel_radius}" length="${wheel_width}"/>
        </geometry>
        <material name="wheel_dark"/>
      </visual>
      <collision>
        <origin xyz="0 0 0" rpy="1.5708 0 0"/>
        <geometry>
          <cylinder radius="${wheel_radius}" length="${wheel_width}"/>
        </geometry>
      </collision>
      <xacro:cylinder_inertial_y_axis mass="${wheel_mass}" radius="${wheel_radius}" length="${wheel_width}"/>
    </link>

    <joint name="${prefix}_wheel_joint" type="continuous">
      <parent link="base_link"/>
      <child link="${prefix}_wheel_link"/>
      <origin xyz="0 ${y_sign * wheel_y} ${wheel_z}" rpy="0 0 0"/>
      <axis xyz="0 1 0"/>
      <dynamics damping="0.05" friction="0.0"/>
    </joint>
  </xacro:macro>

  <xacro:wheel prefix="left" y_sign="1"/>
  <xacro:wheel prefix="right" y_sign="-1"/>

  <link name="caster_link">
    <visual>
      <origin xyz="0 0 0" rpy="0 0 0"/>
      <geometry>
        <sphere radius="${caster_radius}"/>
      </geometry>
      <material name="wheel_dark"/>
    </visual>
    <collision>
      <origin xyz="0 0 0" rpy="0 0 0"/>
      <geometry>
        <sphere radius="${caster_radius}"/>
      </geometry>
    </collision>
    <inertial>
      <mass value="0.05"/>
      <inertia ixx="0.0000125" ixy="0" ixz="0" iyy="0.0000125" iyz="0" izz="0.0000125"/>
    </inertial>
  </link>

  <joint name="caster_joint" type="fixed">
    <parent link="base_link"/>
    <child link="caster_link"/>
    <origin xyz="-0.14 0 ${-base_height / 2.0 + caster_radius}" rpy="0 0 0"/>
  </joint>

  <link name="laser_link">
    <visual>
      <origin xyz="0 0 0" rpy="0 0 0"/>
      <geometry>
        <cylinder radius="0.04" length="0.04"/>
      </geometry>
      <material name="wheel_dark"/>
    </visual>
  </link>

  <joint name="laser_joint" type="fixed">
    <parent link="base_link"/>
    <child link="laser_link"/>
    <origin xyz="0.12 0 0.09" rpy="0 0 0"/>
  </joint>
</robot>
